2025-03-19 15:04:50,219 - ERROR - django.request - Internal Server Error: /fetch_torque_data/
Traceback (most recent call last):
  File "C:\Users\dell\anaconda3\envs\env1\lib\site-packages\asgiref\sync.py", line 518, in thread_handler
    raise exc_info[1]
  File "C:\Users\dell\anaconda3\envs\env1\lib\site-packages\django\core\handlers\exception.py", line 42, in inner
    response = await get_response(request)
  File "C:\Users\dell\anaconda3\envs\env1\lib\site-packages\django\core\handlers\base.py", line 253, in _get_response_async
    response = await wrapped_callback(
  File "C:\Users\dell\anaconda3\envs\env1\lib\site-packages\asgiref\sync.py", line 468, in __call__
    ret = await asyncio.shield(exec_coro)
  File "C:\Users\dell\anaconda3\envs\env1\lib\site-packages\asgiref\current_thread_executor.py", line 40, in run
    result = self.fn(*self.args, **self.kwargs)
  File "C:\Users\dell\anaconda3\envs\env1\lib\site-packages\asgiref\sync.py", line 522, in thread_handler
    return func(*args, **kwargs)
  File "D:\Shubham\BAPL_Rototech\Traceability_BAPL\.\track\views.py", line 99, in fetch_torque_data
    formatted_data = [
  File "D:\Shubham\BAPL_Rototech\Traceability_BAPL\.\track\views.py", line 110, in <listcomp>
    "st6_result": item.st6_result,
AttributeError: 'TraceabilityData' object has no attribute 'st6_result'
2025-03-19 15:04:51,883 - ERROR - django.request - Internal Server Error: /fetch_torque_data/
Traceback (most recent call last):
  File "C:\Users\dell\anaconda3\envs\env1\lib\site-packages\asgiref\sync.py", line 518, in thread_handler
    raise exc_info[1]
  File "C:\Users\dell\anaconda3\envs\env1\lib\site-packages\django\core\handlers\exception.py", line 42, in inner
    response = await get_response(request)
  File "C:\Users\dell\anaconda3\envs\env1\lib\site-packages\django\core\handlers\base.py", line 253, in _get_response_async
    response = await wrapped_callback(
  File "C:\Users\dell\anaconda3\envs\env1\lib\site-packages\asgiref\sync.py", line 468, in __call__
    ret = await asyncio.shield(exec_coro)
  File "C:\Users\dell\anaconda3\envs\env1\lib\site-packages\asgiref\current_thread_executor.py", line 40, in run
    result = self.fn(*self.args, **self.kwargs)
  File "C:\Users\dell\anaconda3\envs\env1\lib\site-packages\asgiref\sync.py", line 522, in thread_handler
    return func(*args, **kwargs)
  File "D:\Shubham\BAPL_Rototech\Traceability_BAPL\.\track\views.py", line 99, in fetch_torque_data
    formatted_data = [
  File "D:\Shubham\BAPL_Rototech\Traceability_BAPL\.\track\views.py", line 110, in <listcomp>
    "st6_result": item.st6_result,
AttributeError: 'TraceabilityData' object has no attribute 'st6_result'
2025-03-19 15:04:54,647 - ERROR - django.request - Internal Server Error: /fetch_torque_data/
Traceback (most recent call last):
  File "C:\Users\dell\anaconda3\envs\env1\lib\site-packages\asgiref\sync.py", line 518, in thread_handler
    raise exc_info[1]
  File "C:\Users\dell\anaconda3\envs\env1\lib\site-packages\django\core\handlers\exception.py", line 42, in inner
    response = await get_response(request)
  File "C:\Users\dell\anaconda3\envs\env1\lib\site-packages\django\core\handlers\base.py", line 253, in _get_response_async
    response = await wrapped_callback(
  File "C:\Users\dell\anaconda3\envs\env1\lib\site-packages\asgiref\sync.py", line 468, in __call__
    ret = await asyncio.shield(exec_coro)
  File "C:\Users\dell\anaconda3\envs\env1\lib\site-packages\asgiref\current_thread_executor.py", line 40, in run
    result = self.fn(*self.args, **self.kwargs)
  File "C:\Users\dell\anaconda3\envs\env1\lib\site-packages\asgiref\sync.py", line 522, in thread_handler
    return func(*args, **kwargs)
  File "D:\Shubham\BAPL_Rototech\Traceability_BAPL\.\track\views.py", line 99, in fetch_torque_data
    formatted_data = [
  File "D:\Shubham\BAPL_Rototech\Traceability_BAPL\.\track\views.py", line 110, in <listcomp>
    "st6_result": item.st6_result,
AttributeError: 'TraceabilityData' object has no attribute 'st6_result'
2025-03-19 15:04:56,812 - ERROR - django.request - Internal Server Error: /fetch_torque_data/
Traceback (most recent call last):
  File "C:\Users\dell\anaconda3\envs\env1\lib\site-packages\asgiref\sync.py", line 518, in thread_handler
    raise exc_info[1]
  File "C:\Users\dell\anaconda3\envs\env1\lib\site-packages\django\core\handlers\exception.py", line 42, in inner
    response = await get_response(request)
  File "C:\Users\dell\anaconda3\envs\env1\lib\site-packages\django\core\handlers\base.py", line 253, in _get_response_async
    response = await wrapped_callback(
  File "C:\Users\dell\anaconda3\envs\env1\lib\site-packages\asgiref\sync.py", line 468, in __call__
    ret = await asyncio.shield(exec_coro)
  File "C:\Users\dell\anaconda3\envs\env1\lib\site-packages\asgiref\current_thread_executor.py", line 40, in run
    result = self.fn(*self.args, **self.kwargs)
  File "C:\Users\dell\anaconda3\envs\env1\lib\site-packages\asgiref\sync.py", line 522, in thread_handler
    return func(*args, **kwargs)
  File "D:\Shubham\BAPL_Rototech\Traceability_BAPL\.\track\views.py", line 99, in fetch_torque_data
    formatted_data = [
  File "D:\Shubham\BAPL_Rototech\Traceability_BAPL\.\track\views.py", line 110, in <listcomp>
    "st6_result": item.st6_result,
AttributeError: 'TraceabilityData' object has no attribute 'st6_result'
2025-03-19 15:05:19,001 - ERROR - django.request - Internal Server Error: /fetch_torque_data/
Traceback (most recent call last):
  File "C:\Users\dell\anaconda3\envs\env1\lib\site-packages\asgiref\sync.py", line 518, in thread_handler
    raise exc_info[1]
  File "C:\Users\dell\anaconda3\envs\env1\lib\site-packages\django\core\handlers\exception.py", line 42, in inner
    response = await get_response(request)
  File "C:\Users\dell\anaconda3\envs\env1\lib\site-packages\django\core\handlers\base.py", line 253, in _get_response_async
    response = await wrapped_callback(
  File "C:\Users\dell\anaconda3\envs\env1\lib\site-packages\asgiref\sync.py", line 468, in __call__
    ret = await asyncio.shield(exec_coro)
  File "C:\Users\dell\anaconda3\envs\env1\lib\site-packages\asgiref\current_thread_executor.py", line 40, in run
    result = self.fn(*self.args, **self.kwargs)
  File "C:\Users\dell\anaconda3\envs\env1\lib\site-packages\asgiref\sync.py", line 522, in thread_handler
    return func(*args, **kwargs)
  File "D:\Shubham\BAPL_Rototech\Traceability_BAPL\.\track\views.py", line 99, in fetch_torque_data
    formatted_data = [
  File "D:\Shubham\BAPL_Rototech\Traceability_BAPL\.\track\views.py", line 110, in <listcomp>
    "st6_result": item.st6_result,
AttributeError: 'TraceabilityData' object has no attribute 'st6_result'
2025-03-19 15:05:21,083 - ERROR - django.request - Internal Server Error: /fetch_torque_data/
Traceback (most recent call last):
  File "C:\Users\dell\anaconda3\envs\env1\lib\site-packages\asgiref\sync.py", line 518, in thread_handler
    raise exc_info[1]
  File "C:\Users\dell\anaconda3\envs\env1\lib\site-packages\django\core\handlers\exception.py", line 42, in inner
    response = await get_response(request)
  File "C:\Users\dell\anaconda3\envs\env1\lib\site-packages\django\core\handlers\base.py", line 253, in _get_response_async
    response = await wrapped_callback(
  File "C:\Users\dell\anaconda3\envs\env1\lib\site-packages\asgiref\sync.py", line 468, in __call__
    ret = await asyncio.shield(exec_coro)
  File "C:\Users\dell\anaconda3\envs\env1\lib\site-packages\asgiref\current_thread_executor.py", line 40, in run
    result = self.fn(*self.args, **self.kwargs)
  File "C:\Users\dell\anaconda3\envs\env1\lib\site-packages\asgiref\sync.py", line 522, in thread_handler
    return func(*args, **kwargs)
  File "D:\Shubham\BAPL_Rototech\Traceability_BAPL\.\track\views.py", line 99, in fetch_torque_data
    formatted_data = [
  File "D:\Shubham\BAPL_Rototech\Traceability_BAPL\.\track\views.py", line 110, in <listcomp>
    "st6_result": item.st6_result,
AttributeError: 'TraceabilityData' object has no attribute 'st6_result'
2025-03-19 15:05:22,217 - ERROR - django.request - Internal Server Error: /fetch_torque_data/
Traceback (most recent call last):
  File "C:\Users\dell\anaconda3\envs\env1\lib\site-packages\asgiref\sync.py", line 518, in thread_handler
    raise exc_info[1]
  File "C:\Users\dell\anaconda3\envs\env1\lib\site-packages\django\core\handlers\exception.py", line 42, in inner
    response = await get_response(request)
  File "C:\Users\dell\anaconda3\envs\env1\lib\site-packages\django\core\handlers\base.py", line 253, in _get_response_async
    response = await wrapped_callback(
  File "C:\Users\dell\anaconda3\envs\env1\lib\site-packages\asgiref\sync.py", line 468, in __call__
    ret = await asyncio.shield(exec_coro)
  File "C:\Users\dell\anaconda3\envs\env1\lib\site-packages\asgiref\current_thread_executor.py", line 40, in run
    result = self.fn(*self.args, **self.kwargs)
  File "C:\Users\dell\anaconda3\envs\env1\lib\site-packages\asgiref\sync.py", line 522, in thread_handler
    return func(*args, **kwargs)
  File "D:\Shubham\BAPL_Rototech\Traceability_BAPL\.\track\views.py", line 99, in fetch_torque_data
    formatted_data = [
  File "D:\Shubham\BAPL_Rototech\Traceability_BAPL\.\track\views.py", line 110, in <listcomp>
    "st6_result": item.st6_result,
AttributeError: 'TraceabilityData' object has no attribute 'st6_result'
2025-03-19 15:05:24,363 - ERROR - django.request - Internal Server Error: /fetch_torque_data/
Traceback (most recent call last):
  File "C:\Users\dell\anaconda3\envs\env1\lib\site-packages\asgiref\sync.py", line 518, in thread_handler
    raise exc_info[1]
  File "C:\Users\dell\anaconda3\envs\env1\lib\site-packages\django\core\handlers\exception.py", line 42, in inner
    response = await get_response(request)
  File "C:\Users\dell\anaconda3\envs\env1\lib\site-packages\django\core\handlers\base.py", line 253, in _get_response_async
    response = await wrapped_callback(
  File "C:\Users\dell\anaconda3\envs\env1\lib\site-packages\asgiref\sync.py", line 468, in __call__
    ret = await asyncio.shield(exec_coro)
  File "C:\Users\dell\anaconda3\envs\env1\lib\site-packages\asgiref\current_thread_executor.py", line 40, in run
    result = self.fn(*self.args, **self.kwargs)
  File "C:\Users\dell\anaconda3\envs\env1\lib\site-packages\asgiref\sync.py", line 522, in thread_handler
    return func(*args, **kwargs)
  File "D:\Shubham\BAPL_Rototech\Traceability_BAPL\.\track\views.py", line 99, in fetch_torque_data
    formatted_data = [
  File "D:\Shubham\BAPL_Rototech\Traceability_BAPL\.\track\views.py", line 110, in <listcomp>
    "st6_result": item.st6_result,
AttributeError: 'TraceabilityData' object has no attribute 'st6_result'
2025-03-19 15:05:33,031 - ERROR - django.request - Internal Server Error: /fetch_torque_data/
Traceback (most recent call last):
  File "C:\Users\dell\anaconda3\envs\env1\lib\site-packages\asgiref\sync.py", line 518, in thread_handler
    raise exc_info[1]
  File "C:\Users\dell\anaconda3\envs\env1\lib\site-packages\django\core\handlers\exception.py", line 42, in inner
    response = await get_response(request)
  File "C:\Users\dell\anaconda3\envs\env1\lib\site-packages\django\core\handlers\base.py", line 253, in _get_response_async
    response = await wrapped_callback(
  File "C:\Users\dell\anaconda3\envs\env1\lib\site-packages\asgiref\sync.py", line 468, in __call__
    ret = await asyncio.shield(exec_coro)
  File "C:\Users\dell\anaconda3\envs\env1\lib\site-packages\asgiref\current_thread_executor.py", line 40, in run
    result = self.fn(*self.args, **self.kwargs)
  File "C:\Users\dell\anaconda3\envs\env1\lib\site-packages\asgiref\sync.py", line 522, in thread_handler
    return func(*args, **kwargs)
  File "D:\Shubham\BAPL_Rototech\Traceability_BAPL\.\track\views.py", line 99, in fetch_torque_data
    formatted_data = [
  File "D:\Shubham\BAPL_Rototech\Traceability_BAPL\.\track\views.py", line 110, in <listcomp>
    "st6_result": item.st6_result,
AttributeError: 'TraceabilityData' object has no attribute 'st6_result'
2025-03-19 15:05:33,178 - ERROR - django.request - Internal Server Error: /fetch_torque_data/
Traceback (most recent call last):
  File "C:\Users\dell\anaconda3\envs\env1\lib\site-packages\asgiref\sync.py", line 518, in thread_handler
    raise exc_info[1]
  File "C:\Users\dell\anaconda3\envs\env1\lib\site-packages\django\core\handlers\exception.py", line 42, in inner
    response = await get_response(request)
  File "C:\Users\dell\anaconda3\envs\env1\lib\site-packages\django\core\handlers\base.py", line 253, in _get_response_async
    response = await wrapped_callback(
  File "C:\Users\dell\anaconda3\envs\env1\lib\site-packages\asgiref\sync.py", line 468, in __call__
    ret = await asyncio.shield(exec_coro)
  File "C:\Users\dell\anaconda3\envs\env1\lib\site-packages\asgiref\current_thread_executor.py", line 40, in run
    result = self.fn(*self.args, **self.kwargs)
  File "C:\Users\dell\anaconda3\envs\env1\lib\site-packages\asgiref\sync.py", line 522, in thread_handler
    return func(*args, **kwargs)
  File "D:\Shubham\BAPL_Rototech\Traceability_BAPL\.\track\views.py", line 99, in fetch_torque_data
    formatted_data = [
  File "D:\Shubham\BAPL_Rototech\Traceability_BAPL\.\track\views.py", line 110, in <listcomp>
    "st6_result": item.st6_result,
AttributeError: 'TraceabilityData' object has no attribute 'st6_result'
2025-03-19 15:05:35,099 - ERROR - django.request - Internal Server Error: /fetch_torque_data/
Traceback (most recent call last):
  File "C:\Users\dell\anaconda3\envs\env1\lib\site-packages\asgiref\sync.py", line 518, in thread_handler
    raise exc_info[1]
  File "C:\Users\dell\anaconda3\envs\env1\lib\site-packages\django\core\handlers\exception.py", line 42, in inner
    response = await get_response(request)
  File "C:\Users\dell\anaconda3\envs\env1\lib\site-packages\django\core\handlers\base.py", line 253, in _get_response_async
    response = await wrapped_callback(
  File "C:\Users\dell\anaconda3\envs\env1\lib\site-packages\asgiref\sync.py", line 468, in __call__
    ret = await asyncio.shield(exec_coro)
  File "C:\Users\dell\anaconda3\envs\env1\lib\site-packages\asgiref\current_thread_executor.py", line 40, in run
    result = self.fn(*self.args, **self.kwargs)
  File "C:\Users\dell\anaconda3\envs\env1\lib\site-packages\asgiref\sync.py", line 522, in thread_handler
    return func(*args, **kwargs)
  File "D:\Shubham\BAPL_Rototech\Traceability_BAPL\.\track\views.py", line 99, in fetch_torque_data
    formatted_data = [
  File "D:\Shubham\BAPL_Rototech\Traceability_BAPL\.\track\views.py", line 110, in <listcomp>
    "st6_result": item.st6_result,
AttributeError: 'TraceabilityData' object has no attribute 'st6_result'
2025-03-19 15:05:35,603 - ERROR - django.request - Internal Server Error: /fetch_torque_data/
Traceback (most recent call last):
  File "C:\Users\dell\anaconda3\envs\env1\lib\site-packages\asgiref\sync.py", line 518, in thread_handler
    raise exc_info[1]
  File "C:\Users\dell\anaconda3\envs\env1\lib\site-packages\django\core\handlers\exception.py", line 42, in inner
    response = await get_response(request)
  File "C:\Users\dell\anaconda3\envs\env1\lib\site-packages\django\core\handlers\base.py", line 253, in _get_response_async
    response = await wrapped_callback(
  File "C:\Users\dell\anaconda3\envs\env1\lib\site-packages\asgiref\sync.py", line 468, in __call__
    ret = await asyncio.shield(exec_coro)
  File "C:\Users\dell\anaconda3\envs\env1\lib\site-packages\asgiref\current_thread_executor.py", line 40, in run
    result = self.fn(*self.args, **self.kwargs)
  File "C:\Users\dell\anaconda3\envs\env1\lib\site-packages\asgiref\sync.py", line 522, in thread_handler
    return func(*args, **kwargs)
  File "D:\Shubham\BAPL_Rototech\Traceability_BAPL\.\track\views.py", line 99, in fetch_torque_data
    formatted_data = [
  File "D:\Shubham\BAPL_Rototech\Traceability_BAPL\.\track\views.py", line 110, in <listcomp>
    "st6_result": item.st6_result,
AttributeError: 'TraceabilityData' object has no attribute 'st6_result'
2025-03-19 15:28:02,962 - ERROR - django.request - Internal Server Error: /favicon.ico
Traceback (most recent call last):
  File "C:\Users\dell\anaconda3\envs\env1\lib\site-packages\asgiref\sync.py", line 518, in thread_handler
    raise exc_info[1]
  File "C:\Users\dell\anaconda3\envs\env1\lib\site-packages\django\core\handlers\exception.py", line 42, in inner
    response = await get_response(request)
  File "C:\Users\dell\anaconda3\envs\env1\lib\site-packages\django\core\handlers\base.py", line 235, in _get_response_async
    callback, callback_args, callback_kwargs = self.resolve_request(request)
  File "C:\Users\dell\anaconda3\envs\env1\lib\site-packages\django\core\handlers\base.py", line 313, in resolve_request
    resolver_match = resolver.resolve(request.path_info)
  File "C:\Users\dell\anaconda3\envs\env1\lib\site-packages\django\urls\resolvers.py", line 663, in resolve
    for pattern in self.url_patterns:
  File "C:\Users\dell\anaconda3\envs\env1\lib\site-packages\django\utils\functional.py", line 57, in __get__
    res = instance.__dict__[self.name] = self.func(instance)
  File "C:\Users\dell\anaconda3\envs\env1\lib\site-packages\django\urls\resolvers.py", line 715, in url_patterns
    patterns = getattr(self.urlconf_module, "urlpatterns", self.urlconf_module)
  File "C:\Users\dell\anaconda3\envs\env1\lib\site-packages\django\utils\functional.py", line 57, in __get__
    res = instance.__dict__[self.name] = self.func(instance)
  File "C:\Users\dell\anaconda3\envs\env1\lib\site-packages\django\urls\resolvers.py", line 708, in urlconf_module
    return import_module(self.urlconf_name)
  File "C:\Users\dell\anaconda3\envs\env1\lib\importlib\__init__.py", line 127, in import_module
    return _bootstrap._gcd_import(name[level:], package, level)
  File "<frozen importlib._bootstrap>", line 1014, in _gcd_import
  File "<frozen importlib._bootstrap>", line 991, in _find_and_load
  File "<frozen importlib._bootstrap>", line 975, in _find_and_load_unlocked
  File "<frozen importlib._bootstrap>", line 671, in _load_unlocked
  File "<frozen importlib._bootstrap_external>", line 843, in exec_module
  File "<frozen importlib._bootstrap>", line 219, in _call_with_frames_removed
  File "D:\Shubham\BAPL_Rototech\Traceability_BAPL\.\Traceability\urls.py", line 22, in <module>
    path('', include('track.urls')),
  File "C:\Users\dell\anaconda3\envs\env1\lib\site-packages\django\urls\conf.py", line 38, in include
    urlconf_module = import_module(urlconf_module)
  File "C:\Users\dell\anaconda3\envs\env1\lib\importlib\__init__.py", line 127, in import_module
    return _bootstrap._gcd_import(name[level:], package, level)
  File "<frozen importlib._bootstrap>", line 1014, in _gcd_import
  File "<frozen importlib._bootstrap>", line 991, in _find_and_load
  File "<frozen importlib._bootstrap>", line 975, in _find_and_load_unlocked
  File "<frozen importlib._bootstrap>", line 671, in _load_unlocked
  File "<frozen importlib._bootstrap_external>", line 843, in exec_module
  File "<frozen importlib._bootstrap>", line 219, in _call_with_frames_removed
  File "D:\Shubham\BAPL_Rototech\Traceability_BAPL\.\track\urls.py", line 2, in <module>
    from .views import plc_status, generate_qr_code_view, fetch_torque_data, combined_page,search_parts
  File "D:\Shubham\BAPL_Rototech\Traceability_BAPL\.\track\views.py", line 116, in <module>
    from .filters import TraceabilityDataFilter
  File "D:\Shubham\BAPL_Rototech\Traceability_BAPL\.\track\filters.py", line 10, in <module>
    class TraceabilityDataFilter(django_filters.FilterSet):
  File "C:\Users\dell\anaconda3\envs\env1\lib\site-packages\django_filters\filterset.py", line 78, in __new__
    new_class.base_filters = new_class.get_filters()
  File "C:\Users\dell\anaconda3\envs\env1\lib\site-packages\django_filters\filterset.py", line 367, in get_filters
    raise TypeError(
TypeError: 'Meta.fields' must not contain non-model field names: PART_NUMBER

During handling of the above exception, another exception occurred:

Traceback (most recent call last):
  File "C:\Users\dell\anaconda3\envs\env1\lib\site-packages\asgiref\sync.py", line 518, in thread_handler
    raise exc_info[1]
  File "C:\Users\dell\anaconda3\envs\env1\lib\site-packages\django\core\handlers\exception.py", line 42, in inner
    response = await get_response(request)
  File "C:\Users\dell\anaconda3\envs\env1\lib\site-packages\django\utils\deprecation.py", line 150, in __acall__
    response = response or await self.get_response(request)
  File "C:\Users\dell\anaconda3\envs\env1\lib\site-packages\django\core\handlers\exception.py", line 44, in inner
    response = await sync_to_async(
  File "C:\Users\dell\anaconda3\envs\env1\lib\site-packages\asgiref\sync.py", line 468, in __call__
    ret = await asyncio.shield(exec_coro)
  File "C:\Users\dell\anaconda3\envs\env1\lib\concurrent\futures\thread.py", line 57, in run
    result = self.fn(*self.args, **self.kwargs)
  File "C:\Users\dell\anaconda3\envs\env1\lib\site-packages\asgiref\sync.py", line 520, in thread_handler
    return func(*args, **kwargs)
  File "C:\Users\dell\anaconda3\envs\env1\lib\site-packages\django\core\handlers\exception.py", line 140, in response_for_exception
    response = handle_uncaught_exception(
  File "C:\Users\dell\anaconda3\envs\env1\lib\site-packages\django\core\handlers\exception.py", line 181, in handle_uncaught_exception
    return debug.technical_500_response(request, *exc_info)
  File "C:\Users\dell\anaconda3\envs\env1\lib\site-packages\django\views\debug.py", line 67, in technical_500_response
    html = reporter.get_traceback_html()
  File "C:\Users\dell\anaconda3\envs\env1\lib\site-packages\django\views\debug.py", line 410, in get_traceback_html
    c = Context(self.get_traceback_data(), use_l10n=False)
  File "C:\Users\dell\anaconda3\envs\env1\lib\site-packages\django\views\debug.py", line 393, in get_traceback_data
    c["raising_view_name"] = get_caller(self.request)
  File "C:\Users\dell\anaconda3\envs\env1\lib\site-packages\django\views\debug.py", line 100, in get_caller
    resolver_match = resolve(request.path)
  File "C:\Users\dell\anaconda3\envs\env1\lib\site-packages\django\urls\base.py", line 24, in resolve
    return get_resolver(urlconf).resolve(path)
  File "C:\Users\dell\anaconda3\envs\env1\lib\site-packages\django\urls\resolvers.py", line 663, in resolve
    for pattern in self.url_patterns:
  File "C:\Users\dell\anaconda3\envs\env1\lib\site-packages\django\utils\functional.py", line 57, in __get__
    res = instance.__dict__[self.name] = self.func(instance)
  File "C:\Users\dell\anaconda3\envs\env1\lib\site-packages\django\urls\resolvers.py", line 715, in url_patterns
    patterns = getattr(self.urlconf_module, "urlpatterns", self.urlconf_module)
  File "C:\Users\dell\anaconda3\envs\env1\lib\site-packages\django\utils\functional.py", line 57, in __get__
    res = instance.__dict__[self.name] = self.func(instance)
  File "C:\Users\dell\anaconda3\envs\env1\lib\site-packages\django\urls\resolvers.py", line 708, in urlconf_module
    return import_module(self.urlconf_name)
  File "C:\Users\dell\anaconda3\envs\env1\lib\importlib\__init__.py", line 127, in import_module
    return _bootstrap._gcd_import(name[level:], package, level)
  File "<frozen importlib._bootstrap>", line 1014, in _gcd_import
  File "<frozen importlib._bootstrap>", line 991, in _find_and_load
  File "<frozen importlib._bootstrap>", line 975, in _find_and_load_unlocked
  File "<frozen importlib._bootstrap>", line 671, in _load_unlocked
  File "<frozen importlib._bootstrap_external>", line 843, in exec_module
  File "<frozen importlib._bootstrap>", line 219, in _call_with_frames_removed
  File "D:\Shubham\BAPL_Rototech\Traceability_BAPL\.\Traceability\urls.py", line 22, in <module>
    path('', include('track.urls')),
  File "C:\Users\dell\anaconda3\envs\env1\lib\site-packages\django\urls\conf.py", line 38, in include
    urlconf_module = import_module(urlconf_module)
  File "C:\Users\dell\anaconda3\envs\env1\lib\importlib\__init__.py", line 127, in import_module
    return _bootstrap._gcd_import(name[level:], package, level)
  File "<frozen importlib._bootstrap>", line 1014, in _gcd_import
  File "<frozen importlib._bootstrap>", line 991, in _find_and_load
  File "<frozen importlib._bootstrap>", line 975, in _find_and_load_unlocked
  File "<frozen importlib._bootstrap>", line 671, in _load_unlocked
  File "<frozen importlib._bootstrap_external>", line 843, in exec_module
  File "<frozen importlib._bootstrap>", line 219, in _call_with_frames_removed
  File "D:\Shubham\BAPL_Rototech\Traceability_BAPL\.\track\urls.py", line 2, in <module>
    from .views import plc_status, generate_qr_code_view, fetch_torque_data, combined_page,search_parts
  File "D:\Shubham\BAPL_Rototech\Traceability_BAPL\.\track\views.py", line 116, in <module>
    from .filters import TraceabilityDataFilter
  File "D:\Shubham\BAPL_Rototech\Traceability_BAPL\.\track\filters.py", line 10, in <module>
    class TraceabilityDataFilter(django_filters.FilterSet):
  File "C:\Users\dell\anaconda3\envs\env1\lib\site-packages\django_filters\filterset.py", line 78, in __new__
    new_class.base_filters = new_class.get_filters()
  File "C:\Users\dell\anaconda3\envs\env1\lib\site-packages\django_filters\filterset.py", line 367, in get_filters
    raise TypeError(
TypeError: 'Meta.fields' must not contain non-model field names: PART_NUMBER

During handling of the above exception, another exception occurred:

Traceback (most recent call last):
  File "C:\Users\dell\anaconda3\envs\env1\lib\site-packages\asgiref\sync.py", line 518, in thread_handler
    raise exc_info[1]
  File "C:\Users\dell\anaconda3\envs\env1\lib\site-packages\django\core\handlers\exception.py", line 42, in inner
    response = await get_response(request)
  File "C:\Users\dell\anaconda3\envs\env1\lib\site-packages\django\utils\deprecation.py", line 150, in __acall__
    response = response or await self.get_response(request)
  File "C:\Users\dell\anaconda3\envs\env1\lib\site-packages\django\core\handlers\exception.py", line 44, in inner
    response = await sync_to_async(
  File "C:\Users\dell\anaconda3\envs\env1\lib\site-packages\asgiref\sync.py", line 468, in __call__
    ret = await asyncio.shield(exec_coro)
  File "C:\Users\dell\anaconda3\envs\env1\lib\concurrent\futures\thread.py", line 57, in run
    result = self.fn(*self.args, **self.kwargs)
  File "C:\Users\dell\anaconda3\envs\env1\lib\site-packages\asgiref\sync.py", line 520, in thread_handler
    return func(*args, **kwargs)
  File "C:\Users\dell\anaconda3\envs\env1\lib\site-packages\django\core\handlers\exception.py", line 140, in response_for_exception
    response = handle_uncaught_exception(
  File "C:\Users\dell\anaconda3\envs\env1\lib\site-packages\django\core\handlers\exception.py", line 181, in handle_uncaught_exception
    return debug.technical_500_response(request, *exc_info)
  File "C:\Users\dell\anaconda3\envs\env1\lib\site-packages\django\views\debug.py", line 67, in technical_500_response
    html = reporter.get_traceback_html()
  File "C:\Users\dell\anaconda3\envs\env1\lib\site-packages\django\views\debug.py", line 410, in get_traceback_html
    c = Context(self.get_traceback_data(), use_l10n=False)
  File "C:\Users\dell\anaconda3\envs\env1\lib\site-packages\django\views\debug.py", line 393, in get_traceback_data
    c["raising_view_name"] = get_caller(self.request)
  File "C:\Users\dell\anaconda3\envs\env1\lib\site-packages\django\views\debug.py", line 100, in get_caller
    resolver_match = resolve(request.path)
  File "C:\Users\dell\anaconda3\envs\env1\lib\site-packages\django\urls\base.py", line 24, in resolve
    return get_resolver(urlconf).resolve(path)
  File "C:\Users\dell\anaconda3\envs\env1\lib\site-packages\django\urls\resolvers.py", line 663, in resolve
    for pattern in self.url_patterns:
  File "C:\Users\dell\anaconda3\envs\env1\lib\site-packages\django\utils\functional.py", line 57, in __get__
    res = instance.__dict__[self.name] = self.func(instance)
  File "C:\Users\dell\anaconda3\envs\env1\lib\site-packages\django\urls\resolvers.py", line 715, in url_patterns
    patterns = getattr(self.urlconf_module, "urlpatterns", self.urlconf_module)
  File "C:\Users\dell\anaconda3\envs\env1\lib\site-packages\django\utils\functional.py", line 57, in __get__
    res = instance.__dict__[self.name] = self.func(instance)
  File "C:\Users\dell\anaconda3\envs\env1\lib\site-packages\django\urls\resolvers.py", line 708, in urlconf_module
    return import_module(self.urlconf_name)
  File "C:\Users\dell\anaconda3\envs\env1\lib\importlib\__init__.py", line 127, in import_module
    return _bootstrap._gcd_import(name[level:], package, level)
  File "<frozen importlib._bootstrap>", line 1014, in _gcd_import
  File "<frozen importlib._bootstrap>", line 991, in _find_and_load
  File "<frozen importlib._bootstrap>", line 975, in _find_and_load_unlocked
  File "<frozen importlib._bootstrap>", line 671, in _load_unlocked
  File "<frozen importlib._bootstrap_external>", line 843, in exec_module
  File "<frozen importlib._bootstrap>", line 219, in _call_with_frames_removed
  File "D:\Shubham\BAPL_Rototech\Traceability_BAPL\.\Traceability\urls.py", line 22, in <module>
    path('', include('track.urls')),
  File "C:\Users\dell\anaconda3\envs\env1\lib\site-packages\django\urls\conf.py", line 38, in include
    urlconf_module = import_module(urlconf_module)
  File "C:\Users\dell\anaconda3\envs\env1\lib\importlib\__init__.py", line 127, in import_module
    return _bootstrap._gcd_import(name[level:], package, level)
  File "<frozen importlib._bootstrap>", line 1014, in _gcd_import
  File "<frozen importlib._bootstrap>", line 991, in _find_and_load
  File "<frozen importlib._bootstrap>", line 975, in _find_and_load_unlocked
  File "<frozen importlib._bootstrap>", line 671, in _load_unlocked
  File "<frozen importlib._bootstrap_external>", line 843, in exec_module
  File "<frozen importlib._bootstrap>", line 219, in _call_with_frames_removed
  File "D:\Shubham\BAPL_Rototech\Traceability_BAPL\.\track\urls.py", line 2, in <module>
    from .views import plc_status, generate_qr_code_view, fetch_torque_data, combined_page,search_parts
  File "D:\Shubham\BAPL_Rototech\Traceability_BAPL\.\track\views.py", line 116, in <module>
    from .filters import TraceabilityDataFilter
  File "D:\Shubham\BAPL_Rototech\Traceability_BAPL\.\track\filters.py", line 10, in <module>
    class TraceabilityDataFilter(django_filters.FilterSet):
  File "C:\Users\dell\anaconda3\envs\env1\lib\site-packages\django_filters\filterset.py", line 78, in __new__
    new_class.base_filters = new_class.get_filters()
  File "C:\Users\dell\anaconda3\envs\env1\lib\site-packages\django_filters\filterset.py", line 367, in get_filters
    raise TypeError(
TypeError: 'Meta.fields' must not contain non-model field names: PART_NUMBER

During handling of the above exception, another exception occurred:

Traceback (most recent call last):
  File "C:\Users\dell\anaconda3\envs\env1\lib\site-packages\asgiref\sync.py", line 518, in thread_handler
    raise exc_info[1]
  File "C:\Users\dell\anaconda3\envs\env1\lib\site-packages\django\core\handlers\exception.py", line 42, in inner
    response = await get_response(request)
  File "C:\Users\dell\anaconda3\envs\env1\lib\site-packages\django\utils\deprecation.py", line 150, in __acall__
    response = response or await self.get_response(request)
  File "C:\Users\dell\anaconda3\envs\env1\lib\site-packages\django\core\handlers\exception.py", line 44, in inner
    response = await sync_to_async(
  File "C:\Users\dell\anaconda3\envs\env1\lib\site-packages\asgiref\sync.py", line 468, in __call__
    ret = await asyncio.shield(exec_coro)
  File "C:\Users\dell\anaconda3\envs\env1\lib\concurrent\futures\thread.py", line 57, in run
    result = self.fn(*self.args, **self.kwargs)
  File "C:\Users\dell\anaconda3\envs\env1\lib\site-packages\asgiref\sync.py", line 520, in thread_handler
    return func(*args, **kwargs)
  File "C:\Users\dell\anaconda3\envs\env1\lib\site-packages\django\core\handlers\exception.py", line 140, in response_for_exception
    response = handle_uncaught_exception(
  File "C:\Users\dell\anaconda3\envs\env1\lib\site-packages\django\core\handlers\exception.py", line 181, in handle_uncaught_exception
    return debug.technical_500_response(request, *exc_info)
  File "C:\Users\dell\anaconda3\envs\env1\lib\site-packages\django\views\debug.py", line 67, in technical_500_response
    html = reporter.get_traceback_html()
  File "C:\Users\dell\anaconda3\envs\env1\lib\site-packages\django\views\debug.py", line 410, in get_traceback_html
    c = Context(self.get_traceback_data(), use_l10n=False)
  File "C:\Users\dell\anaconda3\envs\env1\lib\site-packages\django\views\debug.py", line 393, in get_traceback_data
    c["raising_view_name"] = get_caller(self.request)
  File "C:\Users\dell\anaconda3\envs\env1\lib\site-packages\django\views\debug.py", line 100, in get_caller
    resolver_match = resolve(request.path)
  File "C:\Users\dell\anaconda3\envs\env1\lib\site-packages\django\urls\base.py", line 24, in resolve
    return get_resolver(urlconf).resolve(path)
  File "C:\Users\dell\anaconda3\envs\env1\lib\site-packages\django\urls\resolvers.py", line 663, in resolve
    for pattern in self.url_patterns:
  File "C:\Users\dell\anaconda3\envs\env1\lib\site-packages\django\utils\functional.py", line 57, in __get__
    res = instance.__dict__[self.name] = self.func(instance)
  File "C:\Users\dell\anaconda3\envs\env1\lib\site-packages\django\urls\resolvers.py", line 715, in url_patterns
    patterns = getattr(self.urlconf_module, "urlpatterns", self.urlconf_module)
  File "C:\Users\dell\anaconda3\envs\env1\lib\site-packages\django\utils\functional.py", line 57, in __get__
    res = instance.__dict__[self.name] = self.func(instance)
  File "C:\Users\dell\anaconda3\envs\env1\lib\site-packages\django\urls\resolvers.py", line 708, in urlconf_module
    return import_module(self.urlconf_name)
  File "C:\Users\dell\anaconda3\envs\env1\lib\importlib\__init__.py", line 127, in import_module
    return _bootstrap._gcd_import(name[level:], package, level)
  File "<frozen importlib._bootstrap>", line 1014, in _gcd_import
  File "<frozen importlib._bootstrap>", line 991, in _find_and_load
  File "<frozen importlib._bootstrap>", line 975, in _find_and_load_unlocked
  File "<frozen importlib._bootstrap>", line 671, in _load_unlocked
  File "<frozen importlib._bootstrap_external>", line 843, in exec_module
  File "<frozen importlib._bootstrap>", line 219, in _call_with_frames_removed
  File "D:\Shubham\BAPL_Rototech\Traceability_BAPL\.\Traceability\urls.py", line 22, in <module>
    path('', include('track.urls')),
  File "C:\Users\dell\anaconda3\envs\env1\lib\site-packages\django\urls\conf.py", line 38, in include
    urlconf_module = import_module(urlconf_module)
  File "C:\Users\dell\anaconda3\envs\env1\lib\importlib\__init__.py", line 127, in import_module
    return _bootstrap._gcd_import(name[level:], package, level)
  File "<frozen importlib._bootstrap>", line 1014, in _gcd_import
  File "<frozen importlib._bootstrap>", line 991, in _find_and_load
  File "<frozen importlib._bootstrap>", line 975, in _find_and_load_unlocked
  File "<frozen importlib._bootstrap>", line 671, in _load_unlocked
  File "<frozen importlib._bootstrap_external>", line 843, in exec_module
  File "<frozen importlib._bootstrap>", line 219, in _call_with_frames_removed
  File "D:\Shubham\BAPL_Rototech\Traceability_BAPL\.\track\urls.py", line 2, in <module>
    from .views import plc_status, generate_qr_code_view, fetch_torque_data, combined_page,search_parts
  File "D:\Shubham\BAPL_Rototech\Traceability_BAPL\.\track\views.py", line 116, in <module>
    from .filters import TraceabilityDataFilter
  File "D:\Shubham\BAPL_Rototech\Traceability_BAPL\.\track\filters.py", line 10, in <module>
    class TraceabilityDataFilter(django_filters.FilterSet):
  File "C:\Users\dell\anaconda3\envs\env1\lib\site-packages\django_filters\filterset.py", line 78, in __new__
    new_class.base_filters = new_class.get_filters()
  File "C:\Users\dell\anaconda3\envs\env1\lib\site-packages\django_filters\filterset.py", line 367, in get_filters
    raise TypeError(
TypeError: 'Meta.fields' must not contain non-model field names: PART_NUMBER

During handling of the above exception, another exception occurred:

Traceback (most recent call last):
  File "C:\Users\dell\anaconda3\envs\env1\lib\site-packages\django\core\handlers\exception.py", line 55, in inner
    response = get_response(request)
  File "C:\Users\dell\anaconda3\envs\env1\lib\site-packages\whitenoise\middleware.py", line 124, in __call__
    return self.get_response(request)
  File "C:\Users\dell\anaconda3\envs\env1\lib\site-packages\asgiref\sync.py", line 254, in __call__
    return call_result.result()
  File "C:\Users\dell\anaconda3\envs\env1\lib\concurrent\futures\_base.py", line 437, in result
    return self.__get_result()
  File "C:\Users\dell\anaconda3\envs\env1\lib\concurrent\futures\_base.py", line 389, in __get_result
    raise self._exception
  File "C:\Users\dell\anaconda3\envs\env1\lib\site-packages\asgiref\sync.py", line 331, in main_wrap
    result = await self.awaitable(*args, **kwargs)
  File "C:\Users\dell\anaconda3\envs\env1\lib\site-packages\django\core\handlers\exception.py", line 44, in inner
    response = await sync_to_async(
  File "C:\Users\dell\anaconda3\envs\env1\lib\site-packages\asgiref\sync.py", line 468, in __call__
    ret = await asyncio.shield(exec_coro)
  File "C:\Users\dell\anaconda3\envs\env1\lib\concurrent\futures\thread.py", line 57, in run
    result = self.fn(*self.args, **self.kwargs)
  File "C:\Users\dell\anaconda3\envs\env1\lib\site-packages\asgiref\sync.py", line 520, in thread_handler
    return func(*args, **kwargs)
  File "C:\Users\dell\anaconda3\envs\env1\lib\site-packages\django\core\handlers\exception.py", line 140, in response_for_exception
    response = handle_uncaught_exception(
  File "C:\Users\dell\anaconda3\envs\env1\lib\site-packages\django\core\handlers\exception.py", line 181, in handle_uncaught_exception
    return debug.technical_500_response(request, *exc_info)
  File "C:\Users\dell\anaconda3\envs\env1\lib\site-packages\django\views\debug.py", line 67, in technical_500_response
    html = reporter.get_traceback_html()
  File "C:\Users\dell\anaconda3\envs\env1\lib\site-packages\django\views\debug.py", line 410, in get_traceback_html
    c = Context(self.get_traceback_data(), use_l10n=False)
  File "C:\Users\dell\anaconda3\envs\env1\lib\site-packages\django\views\debug.py", line 393, in get_traceback_data
    c["raising_view_name"] = get_caller(self.request)
  File "C:\Users\dell\anaconda3\envs\env1\lib\site-packages\django\views\debug.py", line 100, in get_caller
    resolver_match = resolve(request.path)
  File "C:\Users\dell\anaconda3\envs\env1\lib\site-packages\django\urls\base.py", line 24, in resolve
    return get_resolver(urlconf).resolve(path)
  File "C:\Users\dell\anaconda3\envs\env1\lib\site-packages\django\urls\resolvers.py", line 663, in resolve
    for pattern in self.url_patterns:
  File "C:\Users\dell\anaconda3\envs\env1\lib\site-packages\django\utils\functional.py", line 57, in __get__
    res = instance.__dict__[self.name] = self.func(instance)
  File "C:\Users\dell\anaconda3\envs\env1\lib\site-packages\django\urls\resolvers.py", line 715, in url_patterns
    patterns = getattr(self.urlconf_module, "urlpatterns", self.urlconf_module)
  File "C:\Users\dell\anaconda3\envs\env1\lib\site-packages\django\utils\functional.py", line 57, in __get__
    res = instance.__dict__[self.name] = self.func(instance)
  File "C:\Users\dell\anaconda3\envs\env1\lib\site-packages\django\urls\resolvers.py", line 708, in urlconf_module
    return import_module(self.urlconf_name)
  File "C:\Users\dell\anaconda3\envs\env1\lib\importlib\__init__.py", line 127, in import_module
    return _bootstrap._gcd_import(name[level:], package, level)
  File "<frozen importlib._bootstrap>", line 1014, in _gcd_import
  File "<frozen importlib._bootstrap>", line 991, in _find_and_load
  File "<frozen importlib._bootstrap>", line 975, in _find_and_load_unlocked
  File "<frozen importlib._bootstrap>", line 671, in _load_unlocked
  File "<frozen importlib._bootstrap_external>", line 843, in exec_module
  File "<frozen importlib._bootstrap>", line 219, in _call_with_frames_removed
  File "D:\Shubham\BAPL_Rototech\Traceability_BAPL\.\Traceability\urls.py", line 22, in <module>
    path('', include('track.urls')),
  File "C:\Users\dell\anaconda3\envs\env1\lib\site-packages\django\urls\conf.py", line 38, in include
    urlconf_module = import_module(urlconf_module)
  File "C:\Users\dell\anaconda3\envs\env1\lib\importlib\__init__.py", line 127, in import_module
    return _bootstrap._gcd_import(name[level:], package, level)
  File "<frozen importlib._bootstrap>", line 1014, in _gcd_import
  File "<frozen importlib._bootstrap>", line 991, in _find_and_load
  File "<frozen importlib._bootstrap>", line 975, in _find_and_load_unlocked
  File "<frozen importlib._bootstrap>", line 671, in _load_unlocked
  File "<frozen importlib._bootstrap_external>", line 843, in exec_module
  File "<frozen importlib._bootstrap>", line 219, in _call_with_frames_removed
  File "D:\Shubham\BAPL_Rototech\Traceability_BAPL\.\track\urls.py", line 2, in <module>
    from .views import plc_status, generate_qr_code_view, fetch_torque_data, combined_page,search_parts
  File "D:\Shubham\BAPL_Rototech\Traceability_BAPL\.\track\views.py", line 116, in <module>
    from .filters import TraceabilityDataFilter
  File "D:\Shubham\BAPL_Rototech\Traceability_BAPL\.\track\filters.py", line 10, in <module>
    class TraceabilityDataFilter(django_filters.FilterSet):
  File "C:\Users\dell\anaconda3\envs\env1\lib\site-packages\django_filters\filterset.py", line 78, in __new__
    new_class.base_filters = new_class.get_filters()
  File "C:\Users\dell\anaconda3\envs\env1\lib\site-packages\django_filters\filterset.py", line 367, in get_filters
    raise TypeError(
TypeError: 'Meta.fields' must not contain non-model field names: PART_NUMBER

During handling of the above exception, another exception occurred:

Traceback (most recent call last):
  File "C:\Users\dell\anaconda3\envs\env1\lib\site-packages\django\core\handlers\exception.py", line 55, in inner
    response = get_response(request)
  File "C:\Users\dell\anaconda3\envs\env1\lib\site-packages\django\utils\deprecation.py", line 134, in __call__
    response = response or self.get_response(request)
  File "C:\Users\dell\anaconda3\envs\env1\lib\site-packages\django\core\handlers\exception.py", line 57, in inner
    response = response_for_exception(request, exc)
  File "C:\Users\dell\anaconda3\envs\env1\lib\site-packages\django\core\handlers\exception.py", line 140, in response_for_exception
    response = handle_uncaught_exception(
  File "C:\Users\dell\anaconda3\envs\env1\lib\site-packages\django\core\handlers\exception.py", line 181, in handle_uncaught_exception
    return debug.technical_500_response(request, *exc_info)
  File "C:\Users\dell\anaconda3\envs\env1\lib\site-packages\django\views\debug.py", line 67, in technical_500_response
    html = reporter.get_traceback_html()
  File "C:\Users\dell\anaconda3\envs\env1\lib\site-packages\django\views\debug.py", line 410, in get_traceback_html
    c = Context(self.get_traceback_data(), use_l10n=False)
  File "C:\Users\dell\anaconda3\envs\env1\lib\site-packages\django\views\debug.py", line 393, in get_traceback_data
    c["raising_view_name"] = get_caller(self.request)
  File "C:\Users\dell\anaconda3\envs\env1\lib\site-packages\django\views\debug.py", line 100, in get_caller
    resolver_match = resolve(request.path)
  File "C:\Users\dell\anaconda3\envs\env1\lib\site-packages\django\urls\base.py", line 24, in resolve
    return get_resolver(urlconf).resolve(path)
  File "C:\Users\dell\anaconda3\envs\env1\lib\site-packages\django\urls\resolvers.py", line 663, in resolve
    for pattern in self.url_patterns:
  File "C:\Users\dell\anaconda3\envs\env1\lib\site-packages\django\utils\functional.py", line 57, in __get__
    res = instance.__dict__[self.name] = self.func(instance)
  File "C:\Users\dell\anaconda3\envs\env1\lib\site-packages\django\urls\resolvers.py", line 715, in url_patterns
    patterns = getattr(self.urlconf_module, "urlpatterns", self.urlconf_module)
  File "C:\Users\dell\anaconda3\envs\env1\lib\site-packages\django\utils\functional.py", line 57, in __get__
    res = instance.__dict__[self.name] = self.func(instance)
  File "C:\Users\dell\anaconda3\envs\env1\lib\site-packages\django\urls\resolvers.py", line 708, in urlconf_module
    return import_module(self.urlconf_name)
  File "C:\Users\dell\anaconda3\envs\env1\lib\importlib\__init__.py", line 127, in import_module
    return _bootstrap._gcd_import(name[level:], package, level)
  File "<frozen importlib._bootstrap>", line 1014, in _gcd_import
  File "<frozen importlib._bootstrap>", line 991, in _find_and_load
  File "<frozen importlib._bootstrap>", line 975, in _find_and_load_unlocked
  File "<frozen importlib._bootstrap>", line 671, in _load_unlocked
  File "<frozen importlib._bootstrap_external>", line 843, in exec_module
  File "<frozen importlib._bootstrap>", line 219, in _call_with_frames_removed
  File "D:\Shubham\BAPL_Rototech\Traceability_BAPL\.\Traceability\urls.py", line 22, in <module>
    path('', include('track.urls')),
  File "C:\Users\dell\anaconda3\envs\env1\lib\site-packages\django\urls\conf.py", line 38, in include
    urlconf_module = import_module(urlconf_module)
  File "C:\Users\dell\anaconda3\envs\env1\lib\importlib\__init__.py", line 127, in import_module
    return _bootstrap._gcd_import(name[level:], package, level)
  File "<frozen importlib._bootstrap>", line 1014, in _gcd_import
  File "<frozen importlib._bootstrap>", line 991, in _find_and_load
  File "<frozen importlib._bootstrap>", line 975, in _find_and_load_unlocked
  File "<frozen importlib._bootstrap>", line 671, in _load_unlocked
  File "<frozen importlib._bootstrap_external>", line 843, in exec_module
  File "<frozen importlib._bootstrap>", line 219, in _call_with_frames_removed
  File "D:\Shubham\BAPL_Rototech\Traceability_BAPL\.\track\urls.py", line 2, in <module>
    from .views import plc_status, generate_qr_code_view, fetch_torque_data, combined_page,search_parts
  File "D:\Shubham\BAPL_Rototech\Traceability_BAPL\.\track\views.py", line 116, in <module>
    from .filters import TraceabilityDataFilter
  File "D:\Shubham\BAPL_Rototech\Traceability_BAPL\.\track\filters.py", line 10, in <module>
    class TraceabilityDataFilter(django_filters.FilterSet):
  File "C:\Users\dell\anaconda3\envs\env1\lib\site-packages\django_filters\filterset.py", line 78, in __new__
    new_class.base_filters = new_class.get_filters()
  File "C:\Users\dell\anaconda3\envs\env1\lib\site-packages\django_filters\filterset.py", line 367, in get_filters
    raise TypeError(
TypeError: 'Meta.fields' must not contain non-model field names: PART_NUMBER

During handling of the above exception, another exception occurred:

Traceback (most recent call last):
  File "C:\Users\dell\anaconda3\envs\env1\lib\site-packages\django\core\handlers\exception.py", line 55, in inner
    response = get_response(request)
  File "C:\Users\dell\anaconda3\envs\env1\lib\site-packages\django\utils\deprecation.py", line 134, in __call__
    response = response or self.get_response(request)
  File "C:\Users\dell\anaconda3\envs\env1\lib\site-packages\django\core\handlers\exception.py", line 57, in inner
    response = response_for_exception(request, exc)
  File "C:\Users\dell\anaconda3\envs\env1\lib\site-packages\django\core\handlers\exception.py", line 140, in response_for_exception
    response = handle_uncaught_exception(
  File "C:\Users\dell\anaconda3\envs\env1\lib\site-packages\django\core\handlers\exception.py", line 181, in handle_uncaught_exception
    return debug.technical_500_response(request, *exc_info)
  File "C:\Users\dell\anaconda3\envs\env1\lib\site-packages\django\views\debug.py", line 67, in technical_500_response
    html = reporter.get_traceback_html()
  File "C:\Users\dell\anaconda3\envs\env1\lib\site-packages\django\views\debug.py", line 410, in get_traceback_html
    c = Context(self.get_traceback_data(), use_l10n=False)
  File "C:\Users\dell\anaconda3\envs\env1\lib\site-packages\django\views\debug.py", line 393, in get_traceback_data
    c["raising_view_name"] = get_caller(self.request)
  File "C:\Users\dell\anaconda3\envs\env1\lib\site-packages\django\views\debug.py", line 100, in get_caller
    resolver_match = resolve(request.path)
  File "C:\Users\dell\anaconda3\envs\env1\lib\site-packages\django\urls\base.py", line 24, in resolve
    return get_resolver(urlconf).resolve(path)
  File "C:\Users\dell\anaconda3\envs\env1\lib\site-packages\django\urls\resolvers.py", line 663, in resolve
    for pattern in self.url_patterns:
  File "C:\Users\dell\anaconda3\envs\env1\lib\site-packages\django\utils\functional.py", line 57, in __get__
    res = instance.__dict__[self.name] = self.func(instance)
  File "C:\Users\dell\anaconda3\envs\env1\lib\site-packages\django\urls\resolvers.py", line 715, in url_patterns
    patterns = getattr(self.urlconf_module, "urlpatterns", self.urlconf_module)
  File "C:\Users\dell\anaconda3\envs\env1\lib\site-packages\django\utils\functional.py", line 57, in __get__
    res = instance.__dict__[self.name] = self.func(instance)
  File "C:\Users\dell\anaconda3\envs\env1\lib\site-packages\django\urls\resolvers.py", line 708, in urlconf_module
    return import_module(self.urlconf_name)
  File "C:\Users\dell\anaconda3\envs\env1\lib\importlib\__init__.py", line 127, in import_module
    return _bootstrap._gcd_import(name[level:], package, level)
  File "<frozen importlib._bootstrap>", line 1014, in _gcd_import
  File "<frozen importlib._bootstrap>", line 991, in _find_and_load
  File "<frozen importlib._bootstrap>", line 975, in _find_and_load_unlocked
  File "<frozen importlib._bootstrap>", line 671, in _load_unlocked
  File "<frozen importlib._bootstrap_external>", line 843, in exec_module
  File "<frozen importlib._bootstrap>", line 219, in _call_with_frames_removed
  File "D:\Shubham\BAPL_Rototech\Traceability_BAPL\.\Traceability\urls.py", line 22, in <module>
    path('', include('track.urls')),
  File "C:\Users\dell\anaconda3\envs\env1\lib\site-packages\django\urls\conf.py", line 38, in include
    urlconf_module = import_module(urlconf_module)
  File "C:\Users\dell\anaconda3\envs\env1\lib\importlib\__init__.py", line 127, in import_module
    return _bootstrap._gcd_import(name[level:], package, level)
  File "<frozen importlib._bootstrap>", line 1014, in _gcd_import
  File "<frozen importlib._bootstrap>", line 991, in _find_and_load
  File "<frozen importlib._bootstrap>", line 975, in _find_and_load_unlocked
  File "<frozen importlib._bootstrap>", line 671, in _load_unlocked
  File "<frozen importlib._bootstrap_external>", line 843, in exec_module
  File "<frozen importlib._bootstrap>", line 219, in _call_with_frames_removed
  File "D:\Shubham\BAPL_Rototech\Traceability_BAPL\.\track\urls.py", line 2, in <module>
    from .views import plc_status, generate_qr_code_view, fetch_torque_data, combined_page,search_parts
  File "D:\Shubham\BAPL_Rototech\Traceability_BAPL\.\track\views.py", line 116, in <module>
    from .filters import TraceabilityDataFilter
  File "D:\Shubham\BAPL_Rototech\Traceability_BAPL\.\track\filters.py", line 10, in <module>
    class TraceabilityDataFilter(django_filters.FilterSet):
  File "C:\Users\dell\anaconda3\envs\env1\lib\site-packages\django_filters\filterset.py", line 78, in __new__
    new_class.base_filters = new_class.get_filters()
  File "C:\Users\dell\anaconda3\envs\env1\lib\site-packages\django_filters\filterset.py", line 367, in get_filters
    raise TypeError(
TypeError: 'Meta.fields' must not contain non-model field names: PART_NUMBER
